<robot name="stapler">

            <link name="base"/>

            <joint name="world_joint" type="fixed">
                <origin rpy="0 0 0" xyz="0 0 0.0"/>
                <parent link="base"/>
                <child link="link_3"/>
            </joint>

            <link name="link_3">
                <visual>
                <geometry>
                    <mesh filename="textured_mesh_3.obj" />
                </geometry>
                <material>
                    <texture filename="textured_mesh_3.png" />
                </material>
                </visual>
                <collision>
                <geometry>
                    <mesh filename="textured_mesh_3.obj" />
                </geometry>
                </collision>
            </link>

            <joint name="link_3_to_link_2" type="revolute">
                <parent link="link_3" />
                <child link="link_2" />
                <origin xyz="0.00010278448462486267 0.00908517837524414 -0.02698822319507599" rpy="0.0 0.0 0.0" />
                <axis xyz="-0.7659048128355673 -0.4246052131784336 -0.48280454701360426" />
                <limit lower="-0.1881982386112213" upper="0.7098816633224487" effort="10" velocity="1.0"/>
                <dynamics damping="0.5"/>
            </joint>

            
            <link name="link_2">
                <visual>
                <geometry>
                    <mesh filename="textured_mesh_2.obj" />
                </geometry>
                <material>
                    <texture filename="textured_mesh_2.png" />
                </material>
                </visual>
                <collision>
                <geometry>
                    <mesh filename="textured_mesh_2.obj" />
                </geometry>
                </collision>
            </link>

            <joint name="link_3_to_link_1" type="revolute">
                <parent link="link_3" />
                <child link="link_1" />
                <origin xyz="0.048319682478904724 -0.020215511322021484 0.04017510265111923" rpy="0.0 0.0 0.0" />
                <axis xyz="-0.9796701125200611 0.1768484628968043 -0.0947158477023165" />
                <limit lower="-0.473804235458374" upper="1.6184465885162354" effort="10" velocity="1.0"/>
                <dynamics damping="0.5"/>
            </joint>
            
            <link name="link_1">
                <visual>
                <geometry>
                    <mesh filename="textured_mesh_1.obj" />
                </geometry>
                <material>
                    <texture filename="textured_mesh_1.png" />
                </material>
                </visual>
                <collision>
                <geometry>
                    <mesh filename="textured_mesh_1.obj" />
                </geometry>
                </collision>
            </link>




             <joint name="link_3_to_link_0" type="revolute">
                <parent link="link_3" />
                <child link="link_0" />
                <origin xyz="-0.02173714153468609 0.017945200204849243 -0.057586535811424255" rpy="0.0 0.0 0.0" />
                <axis xyz="-0.04995648038059518 -0.9832701080878565 -0.17516918852605973" />
                <limit lower="-0.13204704225063324" upper="0.6844573020935059" effort="10" velocity="1.0"/>
                <dynamics damping="0.5"/>
            </joint>
            
            <link name="link_0">
                <visual>
                <geometry>
                    <mesh filename="textured_mesh_0.obj" />
                </geometry>
                <material>
                    <texture filename="textured_mesh_0.png" />
                </material>
                </visual>
                <collision>
                <geometry>
                    <mesh filename="textured_mesh_0.obj" />
                </geometry>
                </collision>
            </link>
            
</robot>